Workbook
Name ListaSucursales: Sucursales!$B$2:INDEX(Sucursales!$B:$B,COUNTA(Sucursales!$B:$B))

Sheet Sucursales
A1: Id de la Sucursal | B1: Nombre de la sucursal | C1: Dirección | D1: Correo | E1: Telefono | F1: Departamento | G1: Municipio | H1: Es franquicia
A2: 117 | B2: Parmessano Santafe Bogota | C2: Calle 185 #45-03 (Local FH9) | D2: parmessano_santafebogota@nca.com.co | E2: 300 6525889 | F2: Bogota D.C. | G2: Bogota D.C. | H2: No
A3: 119 | B3: Parmessano Gran Estacion | C3: Avenida Calle 26 #62-47 | D3: parmessano_granestacion@nca.com.co | E3: 300 6525947 | F3: Bogota D.C. | G3: Bogota D.C. | H3: No
A4: 121 | B4: Parmessano Nuestro Bogota | C4: Avenida Carrera 86 #55A-75 | D4: parmessano_nuestrobogota@nca.com.co | E4: 300 3966697 | F4: Bogota D.C. | G4: Bogota D.C. | H4: No
A5: 116 | B5: Parmessano Atlantis | C5: Calle 81 #13-05 | D5: parmessano_atlantis@nca.com.co | E5: 300 6525879 | F5: Bogota D.C. | G5: Bogota D.C. | H5: No
A6: 122 | B6: Parmessano Atrio | C6: Calle 28 #13A-15 | D6: parmessano_atrio@nca.com.co | E6: 300 3966575 | F6: Bogota D.C. | G6: Bogota D.C. | H6: No
A7: 123 | B7: Parmessano Unicentro | C7: Avenida 15 #124-30 | D7: parmessano_unicentrobgta@nca.com.co | E7: sin linea | F7: Bogota D.C. | G7: Bogota D.C. | H7: No

Sheet Areas y Estaciones
A1: Area de servicio | B1: Estacion
A2: Bar | B2: Jugos
A3: Bar | B3: Sodas
A4: Cocina 1 | B4: Parrilla
A5: Cocina 1 | B5: Freidora / Apanados
A6: Cocina 1 | B6: Cocina Fria
A7: Cocina 1 | B7: pase de cominas
A8: Cocina 2 | B8: Pastas
A9: Cocina 2 | B9: Risottos
A10: Cocina 3 | B10: Stewart
A11: Cocina 3 | B11: Stoker
A12: Salon | B12: Servicio ( Zonas )
... A20: Todo Fresa | B20: Panaderia Y Reposteria

Sheet Estaciones Empleado
A1: Numero de documento | B1: Estacion | C1: Nivel | D1: Sucursal
A2: 912937 | B2: Cocina Fria | C2: BASICO | D2: =IFERROR(_xlfn.XLOOKUP($A2&"",Hoja1!$C$2:$C$253,Hoja1!$D$2:$D$253),IFERROR(_xlfn.XLOOKUP($A2,'Sucursales Empleado'!$A$2:$A$236,'Sucursales Empleado'!$B$2:$B$236),"")) -> Parmessano Atlantis Bogota
A3: 912937 | B3: Risottos | C3: AVANZADO | D3: =IFERROR(_xlfn.XLOOKUP($A3&"",Hoja1!$C$2:$C$253,Hoja1!$D$2:$D$253),IFERROR(_xlfn.XLOOKUP($A3,'Sucursales Empleado'!$A$2:$A$236,'Sucursales Empleado'!$B$2:$B$236),"")) -> Parmessano Atlantis Bogota
A4: 912937 | B4: Freidora / Apanados | C4: AVANZADO | D4: =IFERROR(_xlfn.XLOOKUP($A4&"",Hoja1!$C$2:$C$253,Hoja1!$D$2:$D$253),IFERROR(_xlfn.XLOOKUP($A4,'Sucursales Empleado'!$A$2:$A$236,'Sucursales Empleado'!$B$2:$B$236),"")) -> Parmessano Atlantis Bogota
A5: 912937 | B5: pase de cominas | C5: BASICO | D5: =IFERROR(_xlfn.XLOOKUP($A5&"",Hoja1!$C$2:$C$253,Hoja1!$D$2:$D$253),IFERROR(_xlfn.XLOOKUP($A5,'Sucursales Empleado'!$A$2:$A$236,'Sucursales Empleado'!$B$2:$B$236),"")) -> Parmessano Atlantis Bogota
A6: 912937 | B6: Pastas | C6: AVANZADO | D6: =IFERROR(_xlfn.XLOOKUP($A6&"",Hoja1!$C$2:$C$253,Hoja1!$D$2:$D$253),IFERROR(_xlfn.XLOOKUP($A6,'Sucursales Empleado'!$A$2:$A$236,'Sucursales Empleado'!$B$2:$B$236),"")) -> Parmessano Atlantis Bogota
A7: 912937 | B7: Parrilla | C7: BASICO | D7: =IFERROR(_xlfn.XLOOKUP($A7&"",Hoja1!$C$2:$C$253,Hoja1!$D$2:$D$253),IFERROR(_xlfn.XLOOKUP($A7,'Sucursales Empleado'!$A$2:$A$236,'Sucursales Empleado'!$B$2:$B$236),"")) -> Parmessano Atlantis Bogota
A8: 1410040 | B8: Cocina Fria | C8: AVANZADO | D8: =IFERROR(_xlfn.XLOOKUP($A8&"",Hoja1!$C$2:$C$253,Hoja1!$D$2:$D$253),IFERROR(_xlfn.XLOOKUP($A8,'Sucursales Empleado'!$A$2:$A$236,'Sucursales Empleado'!$B$2:$B$236),"")) -> Parmessano Atlantis Bogota
A9: 1410040 | B9: Risottos | C9: AVANZADO | D9: =IFERROR(_xlfn.XLOOKUP($A9&"",Hoja1!$C$2:$C$253,Hoja1!$D$2:$D$253),IFERROR(_xlfn.XLOOKUP($A9,'Sucursales Empleado'!$A$2:$A$236,'Sucursales Empleado'!$B$2:$B$236),"")) -> Parmessano Atlantis Bogota
A10: 1410040 | B10: Freidora / Apanados | C10: AVANZADO | D10: =IFERROR(_xlfn.XLOOKUP($A10&"",Hoja1!$C$2:$C$253,Hoja1!$D$2:$D$253),IFERROR(_xlfn.XLOOKUP($A10,'Sucursales Empleado'!$A$2:$A$236,'Sucursales Empleado'!$B$2:$B$236),"")) -> Parmessano Atlantis Bogota
A11: 1410040 | B11: pase de cominas | C11: AVANZADO | D11: =IFERROR(_xlfn.XLOOKUP($A11&"",Hoja1!$C$2:$C$253,Hoja1!$D$2:$D$253),IFERROR(_xlfn.XLOOKUP($A11,'Sucursales Empleado'!$A$2:$A$236,'Sucursales Empleado'!$B$2:$B$236),"")) -> Parmessano Atlantis Bogota
A12: 1410040 | B12: Pastas | C12: AVANZADO | D12: =IFERROR(_xlfn.XLOOKUP($A12&"",Hoja1!$C$2:$C$253,Hoja1!$D$2:$D$253),IFERROR(_xlfn.XLOOKUP($A12,'Sucursales Empleado'!$A$2:$A$236,'Sucursales Empleado'!$B$2:$B$236),"")) -> Parmessano Atlantis Bogota
A13: 1410040 | B13: Parrilla | C13: AVANZADO | D13: =IFERROR(_xlfn.XLOOKUP($A13&"",Hoja1!$C$2:$C$253,Hoja1!$D$2:$D$253),IFERROR(_xlfn.XLOOKUP($A13,'Sucursales Empleado'!$A$2:$A$236,'Sucursales Empleado'!$B$2:$B$236),"")) -> Parmessano Atlantis Bogota
... A104: 1101754273 | B104: Fila ( Hostes ) | C104: BASICO | D104: =IFERROR(_xlfn.XLOOKUP($A104&"",Hoja1!$C$2:$C$253,Hoja1!$D$2:$D$253),IFERROR(_xlfn.XLOOKUP($A104,'Sucursales Empleado'!$A$2:$A$236,'Sucursales Empleado'!$B$2:$B$236),"")) -> Parmessano Atlantis Bogota
A105: 52351654 | B105: Jugos | C105: BASICO | D105: =IFERROR(_xlfn.XLOOKUP($A105&"",Hoja1!$C$2:$C$290,Hoja1!$D$2:$D$290),IFERROR(_xlfn.XLOOKUP($A105,'Sucursales Empleado'!$A$2:$A$265,'Sucursales Empleado'!$B$2:$B$265),"")) -> Parmessano Atlantis Bogota
A106: 52351654 | B106: Sodas | C106: BASICO | D106: =IFERROR(_xlfn.XLOOKUP($A106&"",Hoja1!$C$2:$C$290,Hoja1!$D$2:$D$290),IFERROR(_xlfn.XLOOKUP($A106,'Sucursales Empleado'!$A$2:$A$265,'Sucursales Empleado'!$B$2:$B$265),"")) -> Parmessano Atlantis Bogota
A107: 1192899760 | B107: Servicio ( Zonas ) | C107: BASICO | D107: =IFERROR(_xlfn.XLOOKUP($A107&"",Hoja1!$C$2:$C$290,Hoja1!$D$2:$D$290),IFERROR(_xlfn.XLOOKUP($A107,'Sucursales Empleado'!$A$2:$A$265,'Sucursales Empleado'!$B$2:$B$265),"")) -> Parmessano Atlantis Bogota
A108: 1192899760 | B108: patinador de Comidas | C108: BASICO | D108: =IFERROR(_xlfn.XLOOKUP($A108&"",Hoja1!$C$2:$C$290,Hoja1!$D$2:$D$290),IFERROR(_xlfn.XLOOKUP($A108,'Sucursales Empleado'!$A$2:$A$265,'Sucursales Empleado'!$B$2:$B$265),"")) -> Parmessano Atlantis Bogota
A109: 1192899760 | B109: preparacion de bebidas | C109: BASICO | D109: =IFERROR(_xlfn.XLOOKUP($A109&"",Hoja1!$C$2:$C$290,Hoja1!$D$2:$D$290),IFERROR(_xlfn.XLOOKUP($A109,'Sucursales Empleado'!$A$2:$A$265,'Sucursales Empleado'!$B$2:$B$265),"")) -> Parmessano Atlantis Bogota
A110: 1192899760 | B110: Caja | C110: BASICO | D110: =IFERROR(_xlfn.XLOOKUP($A110&"",Hoja1!$C$2:$C$290,Hoja1!$D$2:$D$290),IFERROR(_xlfn.XLOOKUP($A110,'Sucursales Empleado'!$A$2:$A$265,'Sucursales Empleado'!$B$2:$B$265),"")) -> Parmessano Atlantis Bogota
A111: 1192899760 | B111: Panaderia Y Reposteria | C111: BASICO | D111: =IFERROR(_xlfn.XLOOKUP($A111&"",Hoja1!$C$2:$C$290,Hoja1!$D$2:$D$290),IFERROR(_xlfn.XLOOKUP($A111,'Sucursales Empleado'!$A$2:$A$265,'Sucursales Empleado'!$B$2:$B$265),"")) -> Parmessano Atlantis Bogota
A112: 1129500731 | B112: Servicio ( Zonas ) | C112: BASICO | D112: =IFERROR(_xlfn.XLOOKUP($A112&"",Hoja1!$C$2:$C$290,Hoja1!$D$2:$D$290),IFERROR(_xlfn.XLOOKUP($A112,'Sucursales Empleado'!$A$2:$A$265,'Sucursales Empleado'!$B$2:$B$265),"")) -> Parmessano Atlantis Bogota
A113: 1129500731 | B113: patinador de Comidas | C113: BASICO | D113: =IFERROR(_xlfn.XLOOKUP($A113&"",Hoja1!$C$2:$C$290,Hoja1!$D$2:$D$290),IFERROR(_xlfn.XLOOKUP($A113,'Sucursales Empleado'!$A$2:$A$265,'Sucursales Empleado'!$B$2:$B$265),"")) -> Parmessano Atlantis Bogota
A114: 1129500731 | B114: preparacion de bebidas | C114: BASICO | D114: =IFERROR(_xlfn.XLOOKUP($A114&"",Hoja1!$C$2:$C$290,Hoja1!$D$2:$D$290),IFERROR(_xlfn.XLOOKUP($A114,'Sucursales Empleado'!$A$2:$A$265,'Sucursales Empleado'!$B$2:$B$265),"")) -> Parmessano Atlantis Bogota
A115: 1129500731 | B115: Caja | C115: BASICO | D115: =IFERROR(_xlfn.XLOOKUP($A115&"",Hoja1!$C$2:$C$290,Hoja1!$D$2:$D$290),IFERROR(_xlfn.XLOOKUP($A115,'Sucursales Empleado'!$A$2:$A$265,'Sucursales Empleado'!$B$2:$B$265),"")) -> Parmessano Atlantis Bogota
A116: 1129500731 | B116: Panaderia Y Reposteria | C116: BASICO | D116: =IFERROR(_xlfn.XLOOKUP($A116&"",Hoja1!$C$2:$C$290,Hoja1!$D$2:$D$290),IFERROR(_xlfn.XLOOKUP($A116,'Sucursales Empleado'!$A$2:$A$265,'Sucursales Empleado'!$B$2:$B$265),"")) -> Parmessano Atlantis Bogota
... A140: 1054708319 | B140: Fila ( Hostes ) | C140: BASICO | D140: =IFERROR(_xlfn.XLOOKUP($A140&"",Hoja1!$C$2:$C$290,Hoja1!$D$2:$D$290),IFERROR(_xlfn.XLOOKUP($A140,'Sucursales Empleado'!$A$2:$A$265,'Sucursales Empleado'!$B$2:$B$265),"")) -> Parmessano Atlantis Bogota
A141: 5034016 | B141: Cocina Fria | C141: AVANZADO | D141: =IFERROR(_xlfn.XLOOKUP($A141&"",Hoja1!$C$2:$C$253,Hoja1!$D$2:$D$253),IFERROR(_xlfn.XLOOKUP($A141,'Sucursales Empleado'!$A$2:$A$236,'Sucursales Empleado'!$B$2:$B$236),"")) -> Parmessano Atrio
A142: 5034016 | B142: Risottos | C142: AVANZADO | D142: =IFERROR(_xlfn.XLOOKUP($A142&"",Hoja1!$C$2:$C$253,Hoja1!$D$2:$D$253),IFERROR(_xlfn.XLOOKUP($A142,'Sucursales Empleado'!$A$2:$A$236,'Sucursales Empleado'!$B$2:$B$236),"")) -> Parmessano Atrio
A143: 5034016 | B143: Freidora / Apanados | C143: AVANZADO | D143: =IFERROR(_xlfn.XLOOKUP($A143&"",Hoja1!$C$2:$C$253,Hoja1!$D$2:$D$253),IFERROR(_xlfn.XLOOKUP($A143,'Sucursales Empleado'!$A$2:$A$236,'Sucursales Empleado'!$B$2:$B$236),"")) -> Parmessano Atrio
A144: 5034016 | B144: pase de cominas | C144: AVANZADO | D144: =IFERROR(_xlfn.XLOOKUP($A144&"",Hoja1!$C$2:$C$253,Hoja1!$D$2:$D$253),IFERROR(_xlfn.XLOOKUP($A144,'Sucursales Empleado'!$A$2:$A$236,'Sucursales Empleado'!$B$2:$B$236),"")) -> Parmessano Atrio
A145: 5034016 | B145: Pastas | C145: AVANZADO | D145: =IFERROR(_xlfn.XLOOKUP($A145&"",Hoja1!$C$2:$C$253,Hoja1!$D$2:$D$253),IFERROR(_xlfn.XLOOKUP($A145,'Sucursales Empleado'!$A$2:$A$236,'Sucursales Empleado'!$B$2:$B$236),"")) -> Parmessano Atrio
A146: 5034016 | B146: Parrilla | C146: AVANZADO | D146: =IFERROR(_xlfn.XLOOKUP($A146&"",Hoja1!$C$2:$C$253,Hoja1!$D$2:$D$253),IFERROR(_xlfn.XLOOKUP($A146,'Sucursales Empleado'!$A$2:$A$236,'Sucursales Empleado'!$B$2:$B$236),"")) -> Parmessano Atrio
A147: 5844757 | B147: Cocina Fria | C147: INTERMEDIO | D147: =IFERROR(_xlfn.XLOOKUP($A147&"",Hoja1!$C$2:$C$253,Hoja1!$D$2:$D$253),IFERROR(_xlfn.XLOOKUP($A147,'Sucursales Empleado'!$A$2:$A$236,'Sucursales Empleado'!$B$2:$B$236),"")) -> Parmessano Atrio
A148: 5844757 | B148: Risottos | C148: INTERMEDIO | D148: =IFERROR(_xlfn.XLOOKUP($A148&"",Hoja1!$C$2:$C$253,Hoja1!$D$2:$D$253),IFERROR(_xlfn.XLOOKUP($A148,'Sucursales Empleado'!$A$2:$A$236,'Sucursales Empleado'!$B$2:$B$236),"")) -> Parmessano Atrio
A149: 5844757 | B149: Freidora / Apanados | C149: AVANZADO | D149: =IFERROR(_xlfn.XLOOKUP($A149&"",Hoja1!$C$2:$C$253,Hoja1!$D$2:$D$253),IFERROR(_xlfn.XLOOKUP($A149,'Sucursales Empleado'!$A$2:$A$236,'Sucursales Empleado'!$B$2:$B$236),"")) -> Parmessano Atrio
A150: 5844757 | B150: pase de cominas | C150: BASICO | D150: =IFERROR(_xlfn.XLOOKUP($A150&"",Hoja1!$C$2:$C$253,Hoja1!$D$2:$D$253),IFERROR(_xlfn.XLOOKUP($A150,'Sucursales Empleado'!$A$2:$A$236,'Sucursales Empleado'!$B$2:$B$236),"")) -> Parmessano Atrio
A151: 5844757 | B151: Pastas | C151: INTERMEDIO | D151: =IFERROR(_xlfn.XLOOKUP($A151&"",Hoja1!$C$2:$C$253,Hoja1!$D$2:$D$253),IFERROR(_xlfn.XLOOKUP($A151,'Sucursales Empleado'!$A$2:$A$236,'Sucursales Empleado'!$B$2:$B$236),"")) -> Parmessano Atrio
A152: 5844757 | B152: Parrilla | C152: INTERMEDIO | D152: =IFERROR(_xlfn.XLOOKUP($A152&"",Hoja1!$C$2:$C$253,Hoja1!$D$2:$D$253),IFERROR(_xlfn.XLOOKUP($A152,'Sucursales Empleado'!$A$2:$A$236,'Sucursales Empleado'!$B$2:$B$236),"")) -> Parmessano Atrio
... A242: 1004368488 | B242: Fila ( Hostes ) | C242: BASICO | D242: =IFERROR(_xlfn.XLOOKUP($A242&"",Hoja1!$C$2:$C$253,Hoja1!$D$2:$D$253),IFERROR(_xlfn.XLOOKUP($A242,'Sucursales Empleado'!$A$2:$A$236,'Sucursales Empleado'!$B$2:$B$236),"")) -> Parmessano Atrio
...

Sheet Estaciones x Item
A1: Item del menu | B1: Estacion afectada
A2: 8P1485 | B2: Freidora / Apanados
A3: 8P1327 | B3: Cocina Fria
A4: 8P1326 | B4: Cocina Fria
A5: 8T0014 | B5: Sodas
A6: 8P0562 | B6: Cocina Fria
A7: 8P1558 | B7: Pastas
A8: 8P1451 | B8: Parrilla
A9: 8P1487 | B9: Parrilla
A10: 8P0552 | B10: Cocina Fria
A11: 8P0017 | B11: Cocina Fria
A12: 8P0571 | B12: Cocina Fria
... A181: 8P1418 | B181: Parrilla
A182: 8P0057
A183: 8P0295 | B183: Cocina Fria
A184: 8P0531 | B184: Parrilla
A185: 8P1435 | B185: Parrilla
A186: 8P0130 | B186: Parrilla
A187: 8P1552 | B187: Freidora / Apanados
A188: 8T0411 | B188: Panaderia Y Reposteria
A189: 8T0409 | B189: Panaderia Y Reposteria
A190: 8T0408 | B190: Panaderia Y Reposteria
A191: 8T0412 | B191: Panaderia Y Reposteria
A192: 8T0410 | B192: Panaderia Y Reposteria
A193: 8P1549 | B193: Panaderia Y Reposteria
A194: 8T0066 | B194: Panaderia Y Reposteria
... A445: 8P1531 | B445: Sodas

Sheet Estaciones Sucursal
A1: Nombre de la sucursal | B1: Area de servicio | C1: Estacion
A2: Parmessano Santafe Bogota | B2: Cocina 1 | C2: Parrilla
A3: Parmessano Santafe Bogota | B3: Cocina 2 | C3: Pastas
A4: Parmessano Santafe Bogota | B4: Cocina 2 | C4: Risottos
A5: Parmessano Santafe Bogota | B5: Cocina 1 | C5: Freidora / Apanados
A6: Parmessano Santafe Bogota | B6: Cocina 1 | C6: Cocina Fria
A7: Parmessano Santafe Bogota | B7: Cocina 1 | C7: pase de cominas
A8: Parmessano Santafe Bogota | B8: Cocina 3 | C8: Stewart
A9: Parmessano Santafe Bogota | B9: Cocina 3 | C9: Stoker
A10: Parmessano Santafe Bogota | B10: Bar | C10: Jugos
A11: Parmessano Santafe Bogota | B11: Bar | C11: Sodas
A12: Parmessano Santafe Bogota | B12: Todo Fresa | C12: Caja
... A115: Parmessano Unicentro | B115: Salon | C115: Pasa Cuentas

Sheet Horarios Sucursal
A1: Nombre de la sucursal | B1: Dia | C1: Hora de apertura | D1: Hora Inicio Operación | E1: Hora Finalización Operación | F1: Hora de cierre
A2: Parmessano Gran Estacion | B2: LUNES | C2: 06:00 | D2: 08:00 | E2: 21:00 | F2: 22:00
A3: Parmessano Gran Estacion | B3: MARTES | C3: 06:00 | D3: 08:00 | E3: 21:00 | F3: 22:00
A4: Parmessano Gran Estacion | B4: MIERCOLES | C4: 06:00 | D4: 08:00 | E4: 21:00 | F4: 22:00
A5: Parmessano Gran Estacion | B5: JUEVES | C5: 06:00 | D5: 08:00 | E5: 21:00 | F5: 22:00
A6: Parmessano Gran Estacion | B6: VIERNES | C6: 06:00 | D6: 08:00 | E6: 22:00 | F6: 23:00
A7: Parmessano Gran Estacion | B7: SABADO | C7: 06:00 | D7: 08:00 | E7: 22:00 | F7: 23:00
A8: Parmessano Gran Estacion | B8: DOMINGO | C8: 06:00 | D8: 08:00 | E8: 20:00 | F8: 21:00
A9: Parmessano Nuestro Bogota | B9: LUNES | C9: 06:00 | D9: 08:00 | E9: 21:00 | F9: 22:00
A10: Parmessano Nuestro Bogota | B10: MARTES | C10: 06:00 | D10: 08:00 | E10: 21:00 | F10: 22:00
A11: Parmessano Nuestro Bogota | B11: MIERCOLES | C11: 06:00 | D11: 08:00 | E11: 21:00 | F11: 22:00
A12: Parmessano Nuestro Bogota | B12: JUEVES | C12: 06:00 | D12: 08:00 | E12: 21:00 | F12: 22:00
... A43: Parmessano Unicentro | B43: DOMINGO | C43: 06:00 | D43: 08:00 | E43: 20:00 | F43: 21:00

Sheet Descansos
A1: Codigo de vinculacion | B1: Nombre del descanso | C1: Duracion (min) | D1: Opcional
A2: CF | B2: Descanso | C2: 60 | D2: No

Sheet Hoja1
B1: nombre | C1: cedula | D1: sucursal | E1: fecha d einghreso
B2: MARIA ANGELICA SAMUDIO ALVARADO | C2: 1032358964 | D2: Parmessano Atlantis Bogota | E2: 16/08/2024 | H2: MARIA ANGELICA SAMUDIO ALVARADO | I2: 1032358964 | J2: Auxiliar de Cocina
B3: ERICK ANDRE RORIGUEZ BOTINA | C3: 1026590881 | D3: Parmessano Atlantis Bogota | E3: 05/09/2024 | H3: ERICK ANDRE RORIGUEZ BOTINA | I3: 1026590881 | J3: Auxiliar de Cocina
B4: HUGO ELBERTO OMAÑA VARGAS | C4: 79793908 | D4: Parmessano Atlantis Bogota | E4: 04/01/2024 | H4: HUGO ELBERTO OMAÑA VARGAS | I4: 79793908 | J4: Barman
B5: REINALDO DOUGLEN KEY VARGAS | C5: 1019155546 | D5: Parmessano Atlantis Bogota | E5: 28/06/2025 | H5: REINALDO DOUGLEN KEY VARGAS | I5: 1019155546 | J5: Auxiliar de Cocina
B6: EDDIE DIAZ GONZALEZ | C6: 1410040 | D6: Parmessano Atlantis Bogota | E6: 25/07/2025 | H6: EDDIE DIAZ GONZALEZ | I6: 1410040 | J6: Auxiliar de Cocina
B7: MARIA CRISTINA LAMUS GARNICA | C7: 1032411588 | D7: Parmessano Atlantis Bogota | E7: 24/11/2025 | H7: MARIA CRISTINA LAMUS GARNICA | I7: 1032411588 | J7: Asesor(a) de Servicio
B8: ALBERTH NICOLAS NARVAEZ ROBLES | C8: 1014274291 | D8: Parmessano Atlantis Bogota | E8: 25/11/2025 | H8: ALBERTH NICOLAS NARVAEZ ROBLES | I8: 1014274291 | J8: Asesor(a) de Servicio
B9: NICOLAS ALEXANDER GARZON BELTRAN | C9: 1233909318 | D9: Parmessano Atlantis Bogota | E9: 11/05/2024 | H9: NICOLAS ALEXANDER GARZON BELTRAN | I9: 1233909318 | J9: Líder de Cocina
B10: BRAYAN ALFONSO LINARES HERNANDE | C10: 1007718465 | D10: Parmessano Atlantis Bogota | E10: 15/12/2025 | H10: BRAYAN ALFONSO LINARES HERNANDE | I10: 1007718465 | J10: Auxiliar de Cocina
B11: Rebeca Beatriz Villalobos Montero | C11: 6543622 | D11: Parmessano Atlantis Bogota | E11: 12/09/2023 | H11: Rebeca Beatriz Villalobos Montero | I11: 6543622 | J11: Auxiliar de Cocina
B12: JOHAN STIVEN MORENO PINO | C12: 1000580654 | D12: Parmessano Atlantis Bogota | E12: 25/11/2025 | H12: JOHAN STIVEN MORENO PINO | I12: 1000580654 | J12: Barman
B13: LAURA XIMENA VASQUEZ SIERRA | C13: 1018410280 | D13: Parmessano Atlantis Bogota | E13: 20/03/2026 | H13: LAURA XIMENA VASQUEZ SIERRA | I13: 1018410280 | J13: Administrador(a) Junior
... B253: JUANA ALEJANDRA FUQUEN CHACON | C253: 1019988293 | D253: Parmessano Unicentro Bogotá | E253: 23/06/2026 | H253: JUANA ALEJANDRA FUQUEN CHACON | I253: 1019988293 | J253: Auxiliar de Cocina
H254: OSCAR FERNANDO RODRIGUEZ AVENDAÑO | I254: 1022925854 | J254: Administrador(a) Junior
H255: EDWIN ABELARDO CASTILLO MARTINEZ | I255: 80174754 | J255: Cajer@ Junior
H256: MARÍA PAULA MONASTOQUE CASTILLO | I256: 1072717904 | J256: Líder de Cocina
H257: GUILLERMO MARTINEZ MARIN | I257: 4377459 | J257: Cajer@ Junior
H258: ANGEL DAVID CORDOBA MOLINA | I258: 1065833849 | J258: Cajer@ Junior
H259: GERMAN ENRIQUE SANEZ MEZA | I259: 1067726411 | J259: Asesor(a) de Servicio
H260: JORGE GOYO LUCENA | I260: 5176823 | J260: Asesor(a) de Servicio
H261: JOSE VICENTE PEREZ | I261: 79564809 | J261: Asesor(a) de Servicio
H262: YORLIS DANIEL GARCIA MILLAN | I262: 1020807540 | J262: Asesor(a) de Servicio
H263: ARIS ENRIQUE ARGEL NEGRETE | I263: 10904189 | J263: Asesor(a) de Servicio
H264: JUAN ESTEBAN CORREA DIEZ | I264: 1001131334 | J264: Asesor(a) de Servicio
H265: JHONNATAN JAVIER JIMENEZ SANCHEZ | I265: 1000811038 | J265: Asesor(a) de Servicio
... H290: DIANA CAROLINA BONILLA RODRIGUEZ | I290: 1070920153 | J290: Hostess

Sheet Sucursales Empleado
A1: Numero de documento | B1: Sucursal
A2: 1233909318 | B2: Parmessano Atlantis
A3: 1192899760 | B3: Parmessano Atlantis
A4: 1129500731 | B4: Parmessano Atlantis
A5: 1122724152 | B5: Parmessano Atlantis
A6: 1101754273 | B6: Parmessano Atlantis
A7: 1073681374 | B7: Parmessano Atlantis
A8: 1070385532 | B8: Parmessano Atlantis
A9: 1054708319 | B9: Parmessano Atlantis
A10: 1046404608 | B10: Parmessano Atlantis
A11: 1041440332 | B11: Parmessano Atlantis
A12: 1033756966 | B12: Parmessano Atlantis
A13: 1032448692 | B13: Parmessano Atlantis
... A232: 317591 | B232: Parmessano Unicentro

Sheet Actividades
A1: Sucursal | B1: Nombre de la actividad | C1: Tipo | D1: Personas necesarias | E1: Descripción | F1: Día de la semana | G1: Hora de inicio | H1: Hora final | I1: Nombre del empleado | J1: Número de documento | K1: Cargo
A2: Parmessano Santafe Bogota | B2: Alistamiento de apertura | C2: Fijo | D2: 2 por area | E2: Revisión y alistamiento del área antes de iniciar la operación. | F2: Lunes- domingo | G2: =TIMEVALUE('Horarios Sucursal'!C23) -> 0.25 | H2: =TIMEVALUE('Horarios Sucursal'!D23) -> 0.33333333
A3: Parmessano Santafe Bogota | B3: Alistamiento nocturno por área | C3: Fijo | D3: 3 por area | E3: Alistamiento y limpieza nocturna del área entre la finalización de la operación y el cierre. | F3: Lunes- jueves | G3: =TIMEVALUE('Horarios Sucursal'!E23) -> 0.875 | H3: =TIMEVALUE('Horarios Sucursal'!F23) -> 0.91666667
A4: Parmessano Gran Estacion | B4: Alistamiento de apertura | C4: Fijo | D4: 2 por area | E4: Revisión y alistamiento del área antes de iniciar la operación. | F4: Lunes- domingo | G4: =TIMEVALUE('Horarios Sucursal'!C2) -> 0.25 | H4: =TIMEVALUE('Horarios Sucursal'!D2) -> 0.33333333
A5: Parmessano Gran Estacion | B5: Alistamiento nocturno por área | C5: Fijo | D5: 3 por area | E5: Alistamiento y limpieza nocturna del área entre la finalización de la operación y el cierre. | F5: Lunes- jueves | G5: =TIMEVALUE('Horarios Sucursal'!E2) -> 0.875 | H5: =TIMEVALUE('Horarios Sucursal'!F2) -> 0.91666667
A6: Parmessano Nuestro Bogota | B6: Alistamiento de apertura | C6: Fijo | D6: 2 por area | E6: Revisión y alistamiento del área antes de iniciar la operación. | F6: Lunes- domingo | G6: =TIMEVALUE('Horarios Sucursal'!C9) -> 0.25 | H6: =TIMEVALUE('Horarios Sucursal'!D9) -> 0.33333333
A7: Parmessano Nuestro Bogota | B7: Alistamiento nocturno por área | C7: Fijo | D7: 3 por area | E7: Alistamiento y limpieza nocturna del área entre la finalización de la operación y el cierre. | F7: Lunes- jueves | G7: =TIMEVALUE('Horarios Sucursal'!E9) -> 0.875 | H7: =TIMEVALUE('Horarios Sucursal'!F9) -> 0.91666667
A8: Parmessano Atlantis | B8: Alistamiento de apertura | C8: Fijo | D8: 2 por area | E8: Revisión y alistamiento del área antes de iniciar la operación. | F8: Lunes- domingo | G8: =TIMEVALUE('Horarios Sucursal'!C16) -> 0.25 | H8: =TIMEVALUE('Horarios Sucursal'!D16) -> 0.33333333
A9: Parmessano Atlantis | B9: Alistamiento nocturno por área | C9: Fijo | D9: 3 por area | E9: Alistamiento y limpieza nocturna del área entre la finalización de la operación y el cierre. | F9: Lunes- jueves | G9: =TIMEVALUE('Horarios Sucursal'!E16) -> 0.89583333 | H9: =TIMEVALUE('Horarios Sucursal'!F16) -> 0.9375
A10: Parmessano Atrio | B10: Alistamiento de apertura | C10: Fijo | D10: 2 por area | E10: Revisión y alistamiento del área antes de iniciar la operación. | F10: Lunes- domingo | G10: =TIMEVALUE('Horarios Sucursal'!C30) -> 0.20833333 | H10: =TIMEVALUE('Horarios Sucursal'!D30) -> 0.33333333
A11: Parmessano Atrio | B11: Alistamiento nocturno por área | C11: Fijo | D11: 3 por area | E11: Alistamiento y limpieza nocturna del área entre la finalización de la operación y el cierre. | F11: Lunes- jueves | G11: =TIMEVALUE('Horarios Sucursal'!E30) -> 0.875 | H11: =TIMEVALUE('Horarios Sucursal'!F30) -> 0.91666667
A12: Parmessano Unicentro | B12: Alistamiento de apertura | C12: Fijo | D12: 2 por area | E12: Revisión y alistamiento del área antes de iniciar la operación. | F12: Lunes- domingo | G12: =TIMEVALUE('Horarios Sucursal'!C15) -> 0.25 | H12: =TIMEVALUE('Horarios Sucursal'!D15) -> 0.33333333
A13: Parmessano Unicentro | B13: Alistamiento nocturno por área | C13: Fijo | D13: 3 por area | E13: Alistamiento y limpieza nocturna del área entre la finalización de la operación y el cierre. | F13: Lunes- jueves | G13: 0.875 | H13: 0.91666667

Sheet Empleados
A1: Tipo de documento | B1: Numero de documento | C1: Nombre | D1: Telefono | E1: Correo | F1: Departamento | G1: Municipio | H1: Dirección | I1: Tipo de vinculacion | J1: Cargo | K1: Dia dominical
A2: CC | B2: 775317 | C2: MARISOL VALENCIA RIOS | D2: 3505155030 | E2: hofmannerwin95@gmail.com | F2: Bogota D.C. | G2: Bogota D.C. | I2: CF | J2: 2021 | K2: DOMINGO
A3: CC | B3: 912937 | C3: FELIPE DÍAZ DUQUE | D3: 3212532727 | E3: kchun.evs@gmail.com | F3: Bogota D.C. | G3: Bogota D.C. | I3: CF | J3: 2027 | K3: DOMINGO
A4: CC | B4: 1245634 | C4: JUAN JOSE MENDOZA CORDERO | D4: 3116407020 | E4: christianhr1995@gmail.com | F4: Bogota D.C. | G4: Bogota D.C. | I4: CF | J4: 2020 | K4: DOMINGO
A5: CC | B5: 1410040 | C5: JUAN FELIPE GALEANO ROJAS | D5: 3218576986 | E5: eddiejosediaz28@gmail.com | F5: Bogota D.C. | G5: Bogota D.C. | I5: CF | J5: 2020 | K5: DOMINGO
A6: CC | B6: 1424124 | C6: RENE ALBERTO DE BARROETA | D6: 3112471806 | E6: pedrojosemarquina@gmail.com | F6: Bogota D.C. | G6: Bogota D.C. | I6: CF | J6: 2030 | K6: DOMINGO
A7: CC | B7: 1479548 | C7: JOSE RODRIGUEZ HERRERA | D7: 3202764350 | E7: erikagoi@hotmail.com | F7: Bogota D.C. | G7: Bogota D.C. | I7: CF | J7: 2021 | K7: DOMINGO
A8: CC | B8: 1924588 | C8: SHARON YOLITZE DIAZ RAMIREZ | D8: 3150583734 | E8: alex.marchan0101@gmail.com | F8: Bogota D.C. | G8: Bogota D.C. | I8: CF | J8: 2021 | K8: DOMINGO
A9: CC | B9: 2508634 | C9: YULY BIBIANA PILLIMUE ECHEVERRY | D9: 3114962876 | E9: milviannys1@gmail.com | F9: Bogota D.C. | G9: Bogota D.C. | I9: CF | J9: 2020 | K9: DOMINGO
A10: CC | B10: 2947292 | C10: NANCI PAOLA CORPAS ALVARADO | D10: 3144462719 | E10: greypita76@gmail.com | F10: Bogota D.C. | G10: Bogota D.C. | I10: CF | J10: 2020 | K10: DOMINGO
A11: CC | B11: 4134197 | C11: MARÍA ISABEL ALVAREZ CALLE | D11: 3182755580 | E11: jaimevalba27@gmail.com | F11: Bogota D.C. | G11: Bogota D.C. | I11: CF | J11: 2021 | K11: DOMINGO
A12: CC | B12: 4551316 | C12: JHON ALEXANDER PABON VEGA | D12: 3166703074 | E12: yersonmanuel2691@gmail.com | F12: Bogota D.C. | G12: Bogota D.C. | I12: CF | J12: 2021 | K12: DOMINGO
A13: CC | B13: 4648434 | C13: Cristian Javier Morales Sanabria | D13: 3002526758 | E13: jsh.lml91@gmail.com | F13: Bogota D.C. | G13: Bogota D.C. | I13: CF | J13: 2020 | K13: DOMINGO
... A322: CC | B322: 1235240465 | C322: DIEGO ARMANDO GONZALEZ VILORIA | D322: 3502636095 | E322: diegoviloria17@gmail.com | F322: Bogota D.C. | G322: Bogota D.C. | I322: CF | J322: 2021 | K322: DOMINGO

Sheet Productividad
A1: Estacion | B1: Nivel | C1: Promedio de transacciones por hora
A2: Parrilla | B2: AVANZADO | C2: 45
A3: Parrilla | B3: INTERMEDIO | C3: 32
A4: Parrilla | B4: BASICO | C4: 21
A5: Pastas | B5: AVANZADO | C5: 59
A6: Pastas | B6: INTERMEDIO | C6: 42
A7: Pastas | B7: BASICO | C7: 28
A8: Risottos | B8: AVANZADO | C8: 39
A9: Risottos | B9: INTERMEDIO | C9: 28
A10: Risottos | B10: BASICO | C10: 18
A11: Freidora / Apanados | B11: AVANZADO | C11: 65
A12: Freidora / Apanados | B12: INTERMEDIO | C12: 47
A13: Freidora / Apanados | B13: BASICO | C13: 31
... A37: patinador de bebidas | B37: BASICO | C37: 28

Sheet Transacciones
A1: Cant Min Facturas | B1: Cant Max Facturas | C1: Jugos | D1: Sodas | E1: Parrilla | F1: Freidora / Apanados | G1: Cocina Fria | H1: pase de cominas | I1: Pastas | J1: Risottos | K1: Stewart | L1: Servicio ( Zonas ) | M1: patinador de Comidas | N1: Caja / Toma Pedidos | O1: patinador de bebidas | P1: Fila ( Hostes ) | Q1: Pasa Cuentas | R1: Caja | S1: preparacion de bebidas | T1: Panaderia Y Reposteria | U1: Stoker | V1: Total
A2: 0 | B2: 5 | C2: 0 | D2: 1 | E2: 1 | F2: 0 | G2: 1 | H2: 0 | I2: 0 | J2: 0 | K2: 0 | L2: 2 | M2: 0 | N2: 0 | O2: 0 | P2: 0 | Q2: 0 | R2: 0 | S2: 1 | T2: 0 | V2: =SUM(C2:T2) -> 6
A3: =A2+5 -> 5 | B3: =B2+5 -> 10 | C3: 0 | D3: 1 | E3: 1 | F3: 0 | G3: 1 | H3: 0 | I3: 1 | J3: 0 | K3: 0 | L3: 2 | M3: 0 | N3: 0 | O3: 0 | P3: 1 | Q3: 0 | R3: 0 | S3: 1 | T3: 0 | V3: =SUM(C3:T3) -> 8 | Z3: Hora inicio | AA3: Hora Fin | AB3: Cantidad
A4: =A3+5 -> 10 | B4: =B3+5 -> 15 | C4: 0 | D4: 1 | E4: 1 | F4: 0 | G4: 1 | H4: 1 | I4: 1 | J4: 0 | K4: 0 | L4: 2 | M4: 1 | N4: 0 | O4: 0 | P4: 1 | Q4: 0 | R4: 0 | S4: 1 | T4: 1 | V4: =SUM(C4:T4) -> 11 | Y4: administrador | Z4: 0.29166667 | AA4: 0.41666667 | AB4: 1
A5: =A4+5 -> 15 | B5: =B4+5 -> 20 | C5: 0 | D5: 1 | E5: 1 | F5: 1 | G5: 1 | H5: 1 | I5: 1 | J5: 1 | K5: 0 | L5: 2 | M5: 1 | N5: 0 | O5: 0 | P5: 1 | Q5: 0 | R5: 0 | S5: 1 | T5: 1 | V5: =SUM(C5:T5) -> 13 | Y5: administrador | Z5: 0.41666667 | AA5: 0.79166667 | AB5: 2
A6: =A5+5 -> 20 | B6: =B5+5 -> 25 | C6: 1 | D6: 1 | E6: 1 | F6: 1 | G6: 1 | H6: 1 | I6: 1 | J6: 1 | K6: 0 | L6: 3 | M6: 2 | N6: 0 | O6: 1 | P6: 1 | Q6: 0 | R6: 0 | S6: 1 | T6: 1 | V6: =SUM(C6:T6) -> 17 | Y6: administrador | Z6: 0.79166667 | AA6: 0.95833333 | AB6: 1
A7: =A6+5 -> 25 | B7: =B6+5 -> 30 | C7: 1 | D7: 1 | E7: 1 | F7: 1 | G7: 1 | H7: 1 | I7: 1 | J7: 1 | K7: 0 | L7: 3 | M7: 2 | N7: 0 | O7: 1 | P7: 1 | Q7: 1 | R7: 0 | S7: 1 | T7: 1 | V7: =SUM(C7:T7) -> 18 | Y7: bodega | Z7: 0.25 | AA7: 0.58333333 | AB7: 1
A8: =A7+5 -> 30 | B8: =B7+5 -> 35 | C8: 1 | D8: 1 | E8: 1 | F8: 1 | G8: 1 | H8: 1 | I8: 1 | J8: 1 | K8: 1 | L8: 4 | M8: 2 | N8: 1 | O8: 1 | P8: 1 | Q8: 1 | R8: 0 | S8: 1 | T8: 1 | V8: =SUM(C8:T8) -> 21
A9: =A8+5 -> 35 | B9: =B8+5 -> 40 | C9: 1 | D9: 2 | E9: 1 | F9: 1 | G9: 2 | H9: 1 | I9: 1 | J9: 1 | K9: 1 | L9: 4 | M9: 2 | N9: 1 | O9: 1 | P9: 1 | Q9: 1 | R9: 0 | S9: 1 | T9: 1 | V9: =SUM(C9:T9) -> 23
A10: =A9+5 -> 40 | B10: =B9+5 -> 45 | C10: 1 | D10: 2 | E10: 2 | F10: 1 | G10: 2 | H10: 1 | I10: 1 | J10: 1 | K10: 1 | L10: 4 | M10: 2 | N10: 1 | O10: 1 | P10: 1 | Q10: 1 | R10: 0 | S10: 1 | T10: 1 | V10: =SUM(C10:T10) -> 24
A11: =A10+5 -> 45 | B11: =B10+5 -> 50 | C11: 1 | D11: 2 | E11: 2 | F11: 1 | G11: 2 | H11: 1 | I11: 1 | J11: 1 | K11: 1 | L11: 5 | M11: 2 | N11: 1 | O11: 1 | P11: 1 | Q11: 1 | R11: 0 | S11: 1 | T11: 1 | U11: 1 | V11: =SUM(C11:U11) -> 26
C12: =SUM(C2:C11) -> 6
